{"uid":"4b4757e66a1912dae1a509f688f20b0f","children":[{"name":"Test defects","children":[{"name":"urllib3.exceptions.MaxRetryError: HTTPConnectionPool(host='10.1.42.200', port=49152): Max retries exceeded with url: /metrics (Caused by NewConnectionError('<urllib3.connection.HTTPConnection object at 0x7f8805404040>: Failed to establish a new connection: [Errno 111] Connection refused'))","children":[{"name":"test_exporter_endpoint","uid":"58dab07119d2edc4","parentUid":"f3b060e8037632d06c55a75b397c2c6c","status":"broken","time":{"start":1712280594484,"stop":1712280742641,"duration":148157},"flaky":false,"newFailed":false,"newPassed":false,"newBroken":false,"retriesCount":0,"retriesStatusChange":false,"parameters":[],"tags":["asyncio","abort_on_fail","group(1)"]}],"uid":"f3b060e8037632d06c55a75b397c2c6c"}],"uid":"bdbf199525818fae7a8651db9eafe741"}],"name":"categories"}