{"uid":"4b4757e66a1912dae1a509f688f20b0f","children":[{"name":"Test defects","children":[{"name":"urllib3.exceptions.MaxRetryError: HTTPConnectionPool(host='10.1.142.75', port=49152): Max retries exceeded with url: /metrics (Caused by NewConnectionError('<urllib3.connection.HTTPConnection object at 0x7fb5c8bbeb90>: Failed to establish a new connection: [Errno 111] Connection refused'))","children":[{"name":"test_exporter_endpoint","uid":"5378ef0f1065efb0","parentUid":"b7e59c1e5bcdf8b1ba5e4b481661cf68","status":"broken","time":{"start":1712194204709,"stop":1712194344159,"duration":139450},"flaky":false,"newFailed":false,"newPassed":false,"newBroken":true,"retriesCount":0,"retriesStatusChange":false,"parameters":[],"tags":["asyncio","abort_on_fail","group(1)"]}],"uid":"b7e59c1e5bcdf8b1ba5e4b481661cf68"}],"uid":"bdbf199525818fae7a8651db9eafe741"}],"name":"categories"}