[32mINFO    [0m pytest_operator.plugin:plugin.py:790 Model status:

Model  Controller          Cloud/Region        Version  SLA          Timestamp
test   microk8s-localhost  microk8s/localhost  3.1.6    unsupported  01:37:06Z

App                       Version                  Status  Scale  Charm                     Channel        Rev  Address         Exposed  Message
data-integrator                                    active      1  data-integrator           latest/edge     27  10.152.183.210  no       
mysql-k8s                 8.0.36-0ubuntu0.22.04.1  active      3  mysql-k8s                 8.0/edge       137  10.152.183.164  no       
mysql-router-k8s          8.0.36-0ubuntu0.22.04.1  active      1  mysql-router-k8s                           0  10.152.183.211  no       
mysql-test-app            0.0.2                    active      1  mysql-test-app            latest/edge     36  10.152.183.25   no       Last written value=1391
self-signed-certificates                           active      1  self-signed-certificates  latest/stable   72  10.152.183.53   no       

Unit                         Workload  Agent      Address      Ports  Message
data-integrator/0*           active    idle       10.1.164.73         
mysql-k8s/0*                 active    executing  10.1.164.79         Primary
mysql-k8s/1                  active    idle       10.1.164.80         
mysql-k8s/2                  active    idle       10.1.164.81         
mysql-router-k8s/0*          active    idle       10.1.164.74         
mysql-test-app/0*            active    idle       10.1.164.78         Last written value=1391
self-signed-certificates/0*  active    idle       10.1.164.72         

[32mINFO    [0m pytest_operator.plugin:plugin.py:796 Juju error logs:

unit-mysql-k8s-0: 01:33:49 ERROR unit.mysql-k8s/0.juju-log certificates:8: Failed to get member state: mysqld daemon is down
unit-mysql-k8s-2: 01:35:41 ERROR unit.mysql-k8s/2.juju-log database-peers:1: Failed to get cluster status for cluster-cc9933f1f9937c7a6abc16d8f6969028
unit-mysql-k8s-2: 01:35:41 ERROR unit.mysql-k8s/2.juju-log database-peers:1: Failed to get cluster endpoints
Traceback (most recent call last):
  File "/var/lib/juju/agents/unit-mysql-k8s-2/charm/src/mysql_k8s_helpers.py", line 772, in update_endpoints
    rw_endpoints, ro_endpoints, offline = self.get_cluster_endpoints(get_ips=False)
  File "/var/lib/juju/agents/unit-mysql-k8s-2/charm/lib/charms/mysql/v0/mysql.py", line 1903, in get_cluster_endpoints
    raise MySQLGetClusterEndpointsError("Failed to get endpoints from cluster status")
charms.mysql.v0.mysql.MySQLGetClusterEndpointsError: Failed to get endpoints from cluster status
unit-mysql-k8s-2: 01:36:02 ERROR unit.mysql-k8s/2.juju-log database-peers:1: Failed to get cluster status for cluster-cc9933f1f9937c7a6abc16d8f6969028
unit-mysql-k8s-2: 01:36:02 ERROR unit.mysql-k8s/2.juju-log database-peers:1: Failed to get cluster endpoints
Traceback (most recent call last):
  File "/var/lib/juju/agents/unit-mysql-k8s-2/charm/src/mysql_k8s_helpers.py", line 772, in update_endpoints
    rw_endpoints, ro_endpoints, offline = self.get_cluster_endpoints(get_ips=False)
  File "/var/lib/juju/agents/unit-mysql-k8s-2/charm/lib/charms/mysql/v0/mysql.py", line 1903, in get_cluster_endpoints
    raise MySQLGetClusterEndpointsError("Failed to get endpoints from cluster status")
charms.mysql.v0.mysql.MySQLGetClusterEndpointsError: Failed to get endpoints from cluster status
unit-mysql-k8s-2: 01:36:05 ERROR unit.mysql-k8s/2.juju-log database-peers:1: Failed to get cluster status for cluster-cc9933f1f9937c7a6abc16d8f6969028
unit-mysql-k8s-2: 01:36:05 ERROR unit.mysql-k8s/2.juju-log database-peers:1: Failed to get cluster endpoints
Traceback (most recent call last):
  File "/var/lib/juju/agents/unit-mysql-k8s-2/charm/src/mysql_k8s_helpers.py", line 772, in update_endpoints
    rw_endpoints, ro_endpoints, offline = self.get_cluster_endpoints(get_ips=False)
  File "/var/lib/juju/agents/unit-mysql-k8s-2/charm/lib/charms/mysql/v0/mysql.py", line 1903, in get_cluster_endpoints
    raise MySQLGetClusterEndpointsError("Failed to get endpoints from cluster status")
charms.mysql.v0.mysql.MySQLGetClusterEndpointsError: Failed to get endpoints from cluster status
unit-mysql-k8s-2: 01:36:06 ERROR unit.mysql-k8s/2.juju-log database-peers:1: Failed to get cluster status for cluster-cc9933f1f9937c7a6abc16d8f6969028
unit-mysql-k8s-2: 01:36:07 ERROR unit.mysql-k8s/2.juju-log database-peers:1: Failed to get cluster endpoints
Traceback (most recent call last):
  File "/var/lib/juju/agents/unit-mysql-k8s-2/charm/src/mysql_k8s_helpers.py", line 772, in update_endpoints
    rw_endpoints, ro_endpoints, offline = self.get_cluster_endpoints(get_ips=False)
  File "/var/lib/juju/agents/unit-mysql-k8s-2/charm/lib/charms/mysql/v0/mysql.py", line 1903, in get_cluster_endpoints
    raise MySQLGetClusterEndpointsError("Failed to get endpoints from cluster status")
charms.mysql.v0.mysql.MySQLGetClusterEndpointsError: Failed to get endpoints from cluster status

[32mINFO    [0m pytest_operator.plugin:plugin.py:862 Forgetting main...
[31m[1mERROR   [0m websockets.client:protocol.py:1015 data transfer failed
Traceback (most recent call last):
  File "/home/runner/work/mysql-router-k8s-operator/mysql-router-k8s-operator/.tox/integration/lib/python3.10/site-packages/websockets/legacy/protocol.py", line 959, in transfer_data
    message = await self.read_message()
  File "/home/runner/work/mysql-router-k8s-operator/mysql-router-k8s-operator/.tox/integration/lib/python3.10/site-packages/websockets/legacy/protocol.py", line 1029, in read_message
    frame = await self.read_data_frame(max_size=self.max_size)
  File "/home/runner/work/mysql-router-k8s-operator/mysql-router-k8s-operator/.tox/integration/lib/python3.10/site-packages/websockets/legacy/protocol.py", line 1104, in read_data_frame
    frame = await self.read_frame(max_size)
  File "/home/runner/work/mysql-router-k8s-operator/mysql-router-k8s-operator/.tox/integration/lib/python3.10/site-packages/websockets/legacy/protocol.py", line 1161, in read_frame
    frame = await Frame.read(
  File "/home/runner/work/mysql-router-k8s-operator/mysql-router-k8s-operator/.tox/integration/lib/python3.10/site-packages/websockets/legacy/framing.py", line 68, in read
    data = await reader(2)
  File "/usr/lib/python3.10/asyncio/streams.py", line 708, in readexactly
    await self._wait_for_data('readexactly')
  File "/usr/lib/python3.10/asyncio/streams.py", line 501, in _wait_for_data
    await self._waiter
  File "/usr/lib/python3.10/asyncio/selector_events.py", line 924, in write
    n = self._sock.send(data)
OSError: [Errno 9] Bad file descriptor