[32mINFO    [0m integration.test_exporter:test_exporter.py:191 Deploying self-signed-certificates
[32mINFO    [0m juju.model:model.py:2069 Deploying ch:amd64/jammy/self-signed-certificates-72
[32mINFO    [0m juju.model:model.py:2759 Waiting for model:
  self-signed-certificates/0 [allocating] waiting: installing agent
[32mINFO    [0m integration.test_exporter:test_exporter.py:202 Relating mysqlrouter with self-signed-certificates
[33mWARNING [0m juju.model:model.py:1558 relate is deprecated and will be removed. Use integrate instead.
[33mWARNING [0m urllib3.connectionpool:connectionpool.py:823 Retrying (Retry(total=2, connect=None, read=None, redirect=None, status=None)) after connection broken by 'NewConnectionError('<urllib3.connection.HTTPConnection object at 0x7f5a599d1690>: Failed to establish a new connection: [Errno 111] Connection refused')': /metrics
[33mWARNING [0m urllib3.connectionpool:connectionpool.py:823 Retrying (Retry(total=1, connect=None, read=None, redirect=None, status=None)) after connection broken by 'NewConnectionError('<urllib3.connection.HTTPConnection object at 0x7f5a599d3220>: Failed to establish a new connection: [Errno 111] Connection refused')': /metrics
[33mWARNING [0m urllib3.connectionpool:connectionpool.py:823 Retrying (Retry(total=0, connect=None, read=None, redirect=None, status=None)) after connection broken by 'NewConnectionError('<urllib3.connection.HTTPConnection object at 0x7f5a599d16c0>: Failed to establish a new connection: [Errno 111] Connection refused')': /metrics
[32mINFO    [0m integration.test_exporter:test_exporter.py:225 Relating mysqlrouter with grafana agent
[33mWARNING [0m juju.model:model.py:1558 relate is deprecated and will be removed. Use integrate instead.
[33mWARNING [0m urllib3.connectionpool:connectionpool.py:823 Retrying (Retry(total=2, connect=None, read=None, redirect=None, status=None)) after connection broken by 'NewConnectionError('<urllib3.connection.HTTPConnection object at 0x7f5a599d0250>: Failed to establish a new connection: [Errno 111] Connection refused')': /metrics
[33mWARNING [0m urllib3.connectionpool:connectionpool.py:823 Retrying (Retry(total=1, connect=None, read=None, redirect=None, status=None)) after connection broken by 'NewConnectionError('<urllib3.connection.HTTPConnection object at 0x7f5a593402b0>: Failed to establish a new connection: [Errno 111] Connection refused')': /metrics
[33mWARNING [0m urllib3.connectionpool:connectionpool.py:823 Retrying (Retry(total=0, connect=None, read=None, redirect=None, status=None)) after connection broken by 'NewConnectionError('<urllib3.connection.HTTPConnection object at 0x7f5a597372b0>: Failed to establish a new connection: [Errno 111] Connection refused')': /metrics
[32mINFO    [0m integration.test_exporter:test_exporter.py:252 Removing relation between mysqlrouter and grafana agent
[33mWARNING [0m urllib3.connectionpool:connectionpool.py:823 Retrying (Retry(total=2, connect=None, read=None, redirect=None, status=None)) after connection broken by 'NewConnectionError('<urllib3.connection.HTTPConnection object at 0x7f5a597345e0>: Failed to establish a new connection: [Errno 111] Connection refused')': /metrics
[33mWARNING [0m urllib3.connectionpool:connectionpool.py:823 Retrying (Retry(total=1, connect=None, read=None, redirect=None, status=None)) after connection broken by 'NewConnectionError('<urllib3.connection.HTTPConnection object at 0x7f5a5999bb80>: Failed to establish a new connection: [Errno 111] Connection refused')': /metrics
[33mWARNING [0m urllib3.connectionpool:connectionpool.py:823 Retrying (Retry(total=0, connect=None, read=None, redirect=None, status=None)) after connection broken by 'NewConnectionError('<urllib3.connection.HTTPConnection object at 0x7f5a5999b940>: Failed to establish a new connection: [Errno 111] Connection refused')': /metrics
[32mINFO    [0m integration.test_exporter:test_exporter.py:272 Removing relation between mysqlrouter and self-signed-certificates
[32mINFO    [0m pytest_operator.plugin:plugin.py:790 Model status:

Model  Controller          Cloud/Region        Version  SLA          Timestamp
test   microk8s-localhost  microk8s/localhost  3.1.6    unsupported  01:39:46Z

App                       Version                  Status   Scale  Charm                     Channel        Rev  Address         Exposed  Message
grafana-agent-k8s         0.35.2                   waiting      1  grafana-agent-k8s         latest/stable   64  10.152.183.100  no       installing agent
mysql-k8s                 8.0.36-0ubuntu0.22.04.1  active       1  mysql-k8s                 8.0/edge       138  10.152.183.174  no       
mysql-router-k8s          8.0.36-0ubuntu0.22.04.1  active       1  mysql-router-k8s                           0  10.152.183.201  no       
mysql-test-app            0.0.2                    active       1  mysql-test-app            latest/edge     37  10.152.183.247  no       Last written value=1132
self-signed-certificates                           active       1  self-signed-certificates  stable          72  10.152.183.204  no       

Unit                         Workload  Agent  Address     Ports  Message
grafana-agent-k8s/0*         blocked   idle   10.1.97.13         grafana-dashboards-provider: off, grafana-cloud-config: off
mysql-k8s/0*                 active    idle   10.1.97.10         Primary
mysql-router-k8s/0*          active    idle   10.1.97.9          
mysql-test-app/0*            active    idle   10.1.97.12         Last written value=1132
self-signed-certificates/0*  active    idle   10.1.97.14         

[32mINFO    [0m pytest_operator.plugin:plugin.py:796 Juju error logs:


[32mINFO    [0m pytest_operator.plugin:plugin.py:862 Forgetting main...