{"uid":"4b4757e66a1912dae1a509f688f20b0f","children":[{"name":"Test defects","children":[{"name":"juju.errors.JujuUnitError: Unit in error: mysql-router-k8s/0","children":[{"name":"test_build_and_deploy","uid":"8f9f7c78d4388284","parentUid":"cf468523029120b5388938b1040064a8","status":"broken","time":{"start":1718415370102,"stop":1718415406775,"duration":36673},"flaky":false,"newFailed":false,"newPassed":false,"newBroken":true,"retriesCount":1,"retriesStatusChange":true,"parameters":[],"tags":["asyncio","abort_on_fail","@pytest.mark.skipif(False, reason='Skips juju <3.1.x as we have a dependency for self-signed-certificates')","group(1)"]}],"uid":"cf468523029120b5388938b1040064a8"},{"name":"urllib3.exceptions.MaxRetryError: HTTPConnectionPool(host='10.1.6.201', port=49152): Max retries exceeded with url: /metrics (Caused by NewConnectionError('<urllib3.connection.HTTPConnection object at 0x7f4ad73f2ef0>: Failed to establish a new connection: [Errno 111] Connection refused'))","children":[{"name":"test_exporter_endpoint","uid":"def73f0ac2a2c285","parentUid":"1e9093307094236443c46ac157e1fd1f","status":"broken","time":{"start":1718415372933,"stop":1718415676947,"duration":304014},"flaky":false,"newFailed":false,"newPassed":false,"newBroken":true,"retriesCount":1,"retriesStatusChange":true,"parameters":[],"tags":["asyncio","abort_on_fail","group(1)"]}],"uid":"1e9093307094236443c46ac157e1fd1f"}],"uid":"bdbf199525818fae7a8651db9eafe741"}],"name":"categories"}