[32mINFO    [0m pytest_operator.plugin:plugin.py:675 Connecting to existing model microk8s-localhost:test on unspecified cloud
[32mINFO    [0m integration.test_charm:test_charm.py:45 Deploying mysql, mysqlrouter and application
[32mINFO    [0m juju.model:model.py:2069 Deploying ch:amd64/jammy/mysql-test-app-29
[32mINFO    [0m juju.model:model.py:2069 Deploying ch:amd64/jammy/mysql-k8s-120
[32mINFO    [0m juju.model:model.py:2069 Deploying local:jammy/mysql-router-k8s-0
[32mINFO    [0m integration.test_charm:test_charm.py:76 Waiting for mysqlrouter to be in BlockedStatus
[32mINFO    [0m integration.test_charm:test_charm.py:82 Relating mysql, mysqlrouter and application
[33mWARNING [0m juju.model:model.py:1558 relate is deprecated and will be removed. Use integrate instead.
[33mWARNING [0m juju.model:model.py:1558 relate is deprecated and will be removed. Use integrate instead.
[32mINFO    [0m juju.model:model.py:2759 Waiting for model:
  mysql-router-k8s/0 [executing] maintenance: Waiting for container
[32mINFO    [0m juju.model:model.py:2759 Waiting for model:
  mysql-router-k8s/0 [idle] waiting: 
[32mINFO    [0m juju.model:model.py:2759 Waiting for model:
  mysql-router-k8s/0 [idle] waiting: MySQL Server does not have quorum. Will retry next Juju event
[32mINFO    [0m juju.model:model.py:2759 Waiting for model:
  mysql-router-k8s/0 [idle] maintenance: MySQL Router starting
[32mINFO    [0m juju.model:model.py:2759 Waiting for model:
  mysql-router-k8s/0 [idle] maintenance: MySQL Router starting
[32mINFO    [0m juju.model:model.py:2759 Waiting for model:
  mysql-router-k8s/0 [idle] maintenance: MySQL Router starting
[32mINFO    [0m juju.model:model.py:2759 Waiting for model:
  mysql-router-k8s/0 [idle] maintenance: MySQL Router starting
[32mINFO    [0m juju.model:model.py:2759 Waiting for model:
  mysql-router-k8s/0 [idle] maintenance: MySQL Router starting
[32mINFO    [0m juju.model:model.py:2759 Waiting for model:
  mysql-router-k8s/0 [idle] active: 
[32mINFO    [0m juju.model:model.py:2759 Waiting for model:
  mysql-k8s/0 [idle] active: Primary
  mysql-k8s/1 [idle] maintenance: joining the cluster
  mysql-k8s/2 [executing] active: 
  mysql-router-k8s/0 [idle] active: 
  mysql-test-app/0 [idle] active: 
[32mINFO    [0m juju.model:model.py:2759 Waiting for model:
  mysql-k8s/0 [executing] active: Primary
  mysql-k8s/1 [executing] active: 
  mysql-k8s/2 [executing] active:
[32mINFO    [0m pytest_operator.plugin:plugin.py:790 Model status:

Model  Controller          Cloud/Region        Version  SLA          Timestamp
test   microk8s-localhost  microk8s/localhost  3.1.6    unsupported  01:37:21Z

App               Version                  Status  Scale  Charm             Channel      Rev  Address         Exposed  Message
mysql-k8s         8.0.35-0ubuntu0.22.04.1  active      3  mysql-k8s         8.0/edge     120  10.152.183.111  no       
mysql-router-k8s  8.0.35-0ubuntu0.22.04.1  active      1  mysql-router-k8s                 0  10.152.183.195  no       
mysql-test-app    0.0.2                    active      1  mysql-test-app    latest/edge   29  10.152.183.68   no       

Unit                 Workload  Agent  Address     Ports  Message
mysql-k8s/0*         active    idle   10.1.63.77         Primary
mysql-k8s/1          active    idle   10.1.63.78         
mysql-k8s/2          active    idle   10.1.63.79         
mysql-router-k8s/0*  active    idle   10.1.63.73         
mysql-test-app/0*    active    idle   10.1.63.72         

[32mINFO    [0m pytest_operator.plugin:plugin.py:796 Juju error logs:

unit-mysql-router-k8s-0: 01:33:12 ERROR unit.mysql-router-k8s/0.juju-log backend-database:6: Failed to bootstrap router
logged_command=['--bootstrap', 'relation-6:***@mysql-k8s-primary.test.svc.cluster.local:3306', '--strict', '--force', '--conf-set-option', 'http_server.bind_address=127.0.0.1', '--conf-use-gr-notifications']
stderr:
Error: The provided server is currently not in a InnoDB cluster group with quorum and thus may contain inaccurate or outdated data.


unit-mysql-router-k8s-0: 01:33:12 ERROR unit.mysql-router-k8s/0.juju-log backend-database:6: MySQL Server does not have quorum. Will retry next Juju event
unit-mysql-k8s-0: 01:33:39 ERROR unit.mysql-k8s/0.juju-log upgrade:1: Failed to get member state: mysqld daemon is down
unit-mysql-k8s-0: 01:33:59 ERROR unit.mysql-k8s/0.juju-log upgrade:1: Failed to get member state: mysqld daemon is down
unit-mysql-test-app-0: 01:34:14 ERROR unit.mysql-test-app/0.juju-log application-peers:0: Unable to write to the database
Traceback (most recent call last):
  File "/var/lib/juju/agents/unit-mysql-test-app-0/charm/venv/mysql/connector/connection_cext.py", line 291, in _open_connection
    self._cmysql.connect(**cnx_kwargs)
_mysql_connector.MySQLInterfaceError: Can't connect to remote MySQL server

The above exception was the direct cause of the following exception:

Traceback (most recent call last):
  File "/var/lib/juju/agents/unit-mysql-test-app-0/charm/./src/charm.py", line 255, in _write_random_value
    with MySQLConnector(self._database_config) as cursor:
  File "/var/lib/juju/agents/unit-mysql-test-app-0/charm/src/connector.py", line 42, in __enter__
    self.connection = mysql.connector.connect(**self.config)
  File "/var/lib/juju/agents/unit-mysql-test-app-0/charm/venv/mysql/connector/pooling.py", line 293, in connect
    return CMySQLConnection(*args, **kwargs)
  File "/var/lib/juju/agents/unit-mysql-test-app-0/charm/venv/mysql/connector/connection_cext.py", line 120, in __init__
    self.connect(**kwargs)
  File "/var/lib/juju/agents/unit-mysql-test-app-0/charm/venv/mysql/connector/abstracts.py", line 1181, in connect
    self._open_connection()
  File "/var/lib/juju/agents/unit-mysql-test-app-0/charm/venv/mysql/connector/connection_cext.py", line 296, in _open_connection
    raise get_mysql_exception(
mysql.connector.errors.DatabaseError: 2003 (HY000): Can't connect to remote MySQL server

The above exception was the direct cause of the following exception:

Traceback (most recent call last):
  File "/var/lib/juju/agents/unit-mysql-test-app-0/charm/./src/charm.py", line 253, in _write_random_value
    for attempt in Retrying(stop=stop_after_delay(60), wait=wait_fixed(5)):
  File "/var/lib/juju/agents/unit-mysql-test-app-0/charm/venv/tenacity/__init__.py", line 384, in __iter__
    do = self.iter(retry_state=retry_state)
  File "/var/lib/juju/agents/unit-mysql-test-app-0/charm/venv/tenacity/__init__.py", line 363, in iter
    raise retry_exc from fut.exception()
tenacity.RetryError: RetryError[<Future at 0x7f9fa2f33b50 state=finished raised DatabaseError>]
unit-mysql-k8s-0: 01:34:19 ERROR unit.mysql-k8s/0.juju-log upgrade:1: Failed to get member state: mysqld daemon is down
unit-mysql-k8s-0: 01:34:19 ERROR unit.mysql-k8s/0.juju-log upgrade:1: Error getting member state. Avoiding potential cluster crash recovery
unit-mysql-k8s-0: 01:35:00 ERROR unit.mysql-k8s/0.juju-log Failed to flush ERROR LOGS logs.
Traceback (most recent call last):
  File "/var/lib/juju/agents/unit-mysql-k8s-0/charm/src/mysql_k8s_helpers.py", line 666, in _run_mysqlsh_script
    stdout, _ = process.wait_output()
  File "/var/lib/juju/agents/unit-mysql-k8s-0/charm/venv/ops/pebble.py", line 1355, in wait_output
    raise ExecError[AnyStr](self._command, exit_code, out_value, err_value)
ops.pebble.ExecError: non-zero exit code 1 executing ['/usr/bin/mysqlsh', '--no-wizard', '--python', '--verbose=1', '-f', '/tmp/script.py', ';', 'rm', '/tmp/script.py'], stdout='', stderr='Cannot set LC_ALL to locale en_US.UTF-8: No such file or directory\nverbose: 2024-02-04T01:34:20Z: Loading startup files...\nverbose: 2024-02-04T01:34:20Z: Loading plugins...\nverbose: 2024-02-04T01:34:20Z: Connecting to MySQL at: serverconfig@mysql-k8s-0.mysql-k8s-endpoints.test.svc.cluster.local\nTraceback (most recent call last):\n  File "<string>", line 1, in <module>\nValueError: Shell.connect: X protocol error: MySQL server has gone away\nClassic protocol error: MySQL Error 2013 (HY000): Lost connection to MySQL server at \'waiting for initial communication packet\', system error: 110\n\n'

During handling of the above exception, another exception occurred:

Traceback (most recent call last):
  File "/var/lib/juju/agents/unit-mysql-k8s-0/charm/lib/charms/mysql/v0/mysql.py", line 2585, in flush_mysql_logs
    self._run_mysqlsh_script("\n".join(flush_logs_commands))
  File "/var/lib/juju/agents/unit-mysql-k8s-0/charm/src/mysql_k8s_helpers.py", line 669, in _run_mysqlsh_script
    raise MySQLClientError(e.stderr)
charms.mysql.v0.mysql.MySQLClientError: Cannot set LC_ALL to locale en_US.UTF-8: No such file or directory
verbose: 2024-02-04T01:34:20Z: Loading startup files...
verbose: 2024-02-04T01:34:20Z: Loading plugins...
verbose: 2024-02-04T01:34:20Z: Connecting to MySQL at: serverconfig@mysql-k8s-0.mysql-k8s-endpoints.test.svc.cluster.local
Traceback (most recent call last):
  File "<string>", line 1, in <module>
ValueError: Shell.connect: X protocol error: MySQL server has gone away
Classic protocol error: MySQL Error 2013 (HY000): Lost connection to MySQL server at 'waiting for initial communication packet', system error: 110


unit-mysql-k8s-0: 01:35:40 ERROR unit.mysql-k8s/0.juju-log Failed to flush GENERAL LOGS logs.
Traceback (most recent call last):
  File "/var/lib/juju/agents/unit-mysql-k8s-0/charm/src/mysql_k8s_helpers.py", line 666, in _run_mysqlsh_script
    stdout, _ = process.wait_output()
  File "/var/lib/juju/agents/unit-mysql-k8s-0/charm/venv/ops/pebble.py", line 1355, in wait_output
    raise ExecError[AnyStr](self._command, exit_code, out_value, err_value)
ops.pebble.ExecError: non-zero exit code 1 executing ['/usr/bin/mysqlsh', '--no-wizard', '--python', '--verbose=1', '-f', '/tmp/script.py', ';', 'rm', '/tmp/script.py'], stdout='', stderr='Cannot set LC_ALL to locale en_US.UTF-8: No such file or directory\nverbose: 2024-02-04T01:35:00Z: Loading startup files...\nverbose: 2024-02-04T01:35:00Z: Loading plugins...\nverbose: 2024-02-04T01:35:00Z: Connecting to MySQL at: serverconfig@mysql-k8s-0.mysql-k8s-endpoints.test.svc.cluster.local\nTraceback (most recent call last):\n  File "<string>", line 1, in <module>\nValueError: Shell.connect: X protocol error: MySQL server has gone away\nClassic protocol error: MySQL Error 2013 (HY000): Lost connection to MySQL server at \'waiting for initial communication packet\', system error: 110\n\n'

During handling of the above exception, another exception occurred:

Traceback (most recent call last):
  File "/var/lib/juju/agents/unit-mysql-k8s-0/charm/lib/charms/mysql/v0/mysql.py", line 2585, in flush_mysql_logs
    self._run_mysqlsh_script("\n".join(flush_logs_commands))
  File "/var/lib/juju/agents/unit-mysql-k8s-0/charm/src/mysql_k8s_helpers.py", line 669, in _run_mysqlsh_script
    raise MySQLClientError(e.stderr)
charms.mysql.v0.mysql.MySQLClientError: Cannot set LC_ALL to locale en_US.UTF-8: No such file or directory
verbose: 2024-02-04T01:35:00Z: Loading startup files...
verbose: 2024-02-04T01:35:00Z: Loading plugins...
verbose: 2024-02-04T01:35:00Z: Connecting to MySQL at: serverconfig@mysql-k8s-0.mysql-k8s-endpoints.test.svc.cluster.local
Traceback (most recent call last):
  File "<string>", line 1, in <module>
ValueError: Shell.connect: X protocol error: MySQL server has gone away
Classic protocol error: MySQL Error 2013 (HY000): Lost connection to MySQL server at 'waiting for initial communication packet', system error: 110



[32mINFO    [0m pytest_operator.plugin:plugin.py:862 Forgetting main...
[31m[1mERROR   [0m websockets.client:protocol.py:1015 data transfer failed
Traceback (most recent call last):
  File "/home/runner/work/mysql-router-k8s-operator/mysql-router-k8s-operator/.tox/integration/lib/python3.10/site-packages/websockets/legacy/protocol.py", line 959, in transfer_data
    message = await self.read_message()
  File "/home/runner/work/mysql-router-k8s-operator/mysql-router-k8s-operator/.tox/integration/lib/python3.10/site-packages/websockets/legacy/protocol.py", line 1029, in read_message
    frame = await self.read_data_frame(max_size=self.max_size)
  File "/home/runner/work/mysql-router-k8s-operator/mysql-router-k8s-operator/.tox/integration/lib/python3.10/site-packages/websockets/legacy/protocol.py", line 1104, in read_data_frame
    frame = await self.read_frame(max_size)
  File "/home/runner/work/mysql-router-k8s-operator/mysql-router-k8s-operator/.tox/integration/lib/python3.10/site-packages/websockets/legacy/protocol.py", line 1161, in read_frame
    frame = await Frame.read(
  File "/home/runner/work/mysql-router-k8s-operator/mysql-router-k8s-operator/.tox/integration/lib/python3.10/site-packages/websockets/legacy/framing.py", line 68, in read
    data = await reader(2)
  File "/usr/lib/python3.10/asyncio/streams.py", line 708, in readexactly
    await self._wait_for_data('readexactly')
  File "/usr/lib/python3.10/asyncio/streams.py", line 501, in _wait_for_data
    await self._waiter
  File "/usr/lib/python3.10/asyncio/selector_events.py", line 924, in write
    n = self._sock.send(data)
OSError: [Errno 9] Bad file descriptor