{"uid":"8eff7307c20b8ed7","name":"test_exporter_endpoint","fullName":"tests.integration.test_exporter#test_exporter_endpoint","historyId":"09cd1fce678fbe30fe0a320d069036b7","time":{"start":1714786525979,"stop":1714786824144,"duration":298165},"description":"Test that exporter endpoint is functional.","descriptionHtml":"<p>Test that exporter endpoint is functional.</p>\n","status":"broken","statusMessage":"urllib3.exceptions.MaxRetryError: HTTPConnectionPool(host='10.1.208.202', port=49152): Max retries exceeded with url: /metrics (Caused by NewConnectionError('<urllib3.connection.HTTPConnection object at 0x7f62886bd3f0>: Failed to establish a new connection: [Errno 111] Connection refused'))","statusTrace":"Traceback (most recent call last):\n  File \"/home/runner/work/mysql-router-k8s-operator/mysql-router-k8s-operator/.tox/integration/lib/python3.10/site-packages/urllib3/connection.py\", line 174, in _new_conn\n    conn = connection.create_connection(\n  File \"/home/runner/work/mysql-router-k8s-operator/mysql-router-k8s-operator/.tox/integration/lib/python3.10/site-packages/urllib3/util/connection.py\", line 95, in create_connection\n    raise err\n  File \"/home/runner/work/mysql-router-k8s-operator/mysql-router-k8s-operator/.tox/integration/lib/python3.10/site-packages/urllib3/util/connection.py\", line 85, in create_connection\n    sock.connect(sa)\nConnectionRefusedError: [Errno 111] Connection refused\n\nDuring handling of the above exception, another exception occurred:\n\nTraceback (most recent call last):\n  File \"/home/runner/work/mysql-router-k8s-operator/mysql-router-k8s-operator/.tox/integration/lib/python3.10/site-packages/urllib3/connectionpool.py\", line 714, in urlopen\n    httplib_response = self._make_request(\n  File \"/home/runner/work/mysql-router-k8s-operator/mysql-router-k8s-operator/.tox/integration/lib/python3.10/site-packages/urllib3/connectionpool.py\", line 415, in _make_request\n    conn.request(method, url, **httplib_request_kw)\n  File \"/home/runner/work/mysql-router-k8s-operator/mysql-router-k8s-operator/.tox/integration/lib/python3.10/site-packages/urllib3/connection.py\", line 244, in request\n    super(HTTPConnection, self).request(method, url, body=body, headers=headers)\n  File \"/usr/lib/python3.10/http/client.py\", line 1283, in request\n    self._send_request(method, url, body, headers, encode_chunked)\n  File \"/usr/lib/python3.10/http/client.py\", line 1329, in _send_request\n    self.endheaders(body, encode_chunked=encode_chunked)\n  File \"/usr/lib/python3.10/http/client.py\", line 1278, in endheaders\n    self._send_output(message_body, encode_chunked=encode_chunked)\n  File \"/usr/lib/python3.10/http/client.py\", line 1038, in _send_output\n    self.send(msg)\n  File \"/usr/lib/python3.10/http/client.py\", line 976, in send\n    self.connect()\n  File \"/home/runner/work/mysql-router-k8s-operator/mysql-router-k8s-operator/.tox/integration/lib/python3.10/site-packages/urllib3/connection.py\", line 205, in connect\n    conn = self._new_conn()\n  File \"/home/runner/work/mysql-router-k8s-operator/mysql-router-k8s-operator/.tox/integration/lib/python3.10/site-packages/urllib3/connection.py\", line 186, in _new_conn\n    raise NewConnectionError(\nurllib3.exceptions.NewConnectionError: <urllib3.connection.HTTPConnection object at 0x7f62886bd3f0>: Failed to establish a new connection: [Errno 111] Connection refused\n\nDuring handling of the above exception, another exception occurred:\n\nTraceback (most recent call last):\n  File \"/home/runner/work/mysql-router-k8s-operator/mysql-router-k8s-operator/.tox/integration/lib/python3.10/site-packages/_pytest/runner.py\", line 341, in from_call\n    result: Optional[TResult] = func()\n  File \"/home/runner/work/mysql-router-k8s-operator/mysql-router-k8s-operator/.tox/integration/lib/python3.10/site-packages/_pytest/runner.py\", line 262, in <lambda>\n    lambda: ihook(item=item, **kwds), when=when, reraise=reraise\n  File \"/home/runner/work/mysql-router-k8s-operator/mysql-router-k8s-operator/.tox/integration/lib/python3.10/site-packages/pluggy/_hooks.py\", line 493, in __call__\n    return self._hookexec(self.name, self._hookimpls, kwargs, firstresult)\n  File \"/home/runner/work/mysql-router-k8s-operator/mysql-router-k8s-operator/.tox/integration/lib/python3.10/site-packages/pluggy/_manager.py\", line 115, in _hookexec\n    return self._inner_hookexec(hook_name, methods, kwargs, firstresult)\n  File \"/home/runner/work/mysql-router-k8s-operator/mysql-router-k8s-operator/.tox/integration/lib/python3.10/site-packages/pluggy/_callers.py\", line 152, in _multicall\n    return outcome.get_result()\n  File \"/home/runner/work/mysql-router-k8s-operator/mysql-router-k8s-operator/.tox/integration/lib/python3.10/site-packages/pluggy/_result.py\", line 114, in get_result\n    raise exc.with_traceback(exc.__traceback__)\n  File \"/home/runner/work/mysql-router-k8s-operator/mysql-router-k8s-operator/.tox/integration/lib/python3.10/site-packages/pluggy/_callers.py\", line 77, in _multicall\n    res = hook_impl.function(*args)\n  File \"/home/runner/work/mysql-router-k8s-operator/mysql-router-k8s-operator/.tox/integration/lib/python3.10/site-packages/_pytest/runner.py\", line 177, in pytest_runtest_call\n    raise e\n  File \"/home/runner/work/mysql-router-k8s-operator/mysql-router-k8s-operator/.tox/integration/lib/python3.10/site-packages/_pytest/runner.py\", line 169, in pytest_runtest_call\n    item.runtest()\n  File \"/home/runner/work/mysql-router-k8s-operator/mysql-router-k8s-operator/.tox/integration/lib/python3.10/site-packages/_pytest/python.py\", line 1788, in runtest\n    self.ihook.pytest_pyfunc_call(pyfuncitem=self)\n  File \"/home/runner/work/mysql-router-k8s-operator/mysql-router-k8s-operator/.tox/integration/lib/python3.10/site-packages/pluggy/_hooks.py\", line 493, in __call__\n    return self._hookexec(self.name, self._hookimpls, kwargs, firstresult)\n  File \"/home/runner/work/mysql-router-k8s-operator/mysql-router-k8s-operator/.tox/integration/lib/python3.10/site-packages/pluggy/_manager.py\", line 115, in _hookexec\n    return self._inner_hookexec(hook_name, methods, kwargs, firstresult)\n  File \"/home/runner/work/mysql-router-k8s-operator/mysql-router-k8s-operator/.tox/integration/lib/python3.10/site-packages/pluggy/_callers.py\", line 152, in _multicall\n    return outcome.get_result()\n  File \"/home/runner/work/mysql-router-k8s-operator/mysql-router-k8s-operator/.tox/integration/lib/python3.10/site-packages/pluggy/_result.py\", line 114, in get_result\n    raise exc.with_traceback(exc.__traceback__)\n  File \"/home/runner/work/mysql-router-k8s-operator/mysql-router-k8s-operator/.tox/integration/lib/python3.10/site-packages/pluggy/_callers.py\", line 77, in _multicall\n    res = hook_impl.function(*args)\n  File \"/home/runner/work/mysql-router-k8s-operator/mysql-router-k8s-operator/.tox/integration/lib/python3.10/site-packages/_pytest/python.py\", line 194, in pytest_pyfunc_call\n    result = testfunction(**testargs)\n  File \"/home/runner/work/mysql-router-k8s-operator/mysql-router-k8s-operator/.tox/integration/lib/python3.10/site-packages/pytest_asyncio/plugin.py\", line 532, in inner\n    _loop.run_until_complete(task)\n  File \"/usr/lib/python3.10/asyncio/base_events.py\", line 649, in run_until_complete\n    return future.result()\n  File \"/home/runner/work/mysql-router-k8s-operator/mysql-router-k8s-operator/tests/integration/test_exporter.py\", line 137, in test_exporter_endpoint\n    for attempt in tenacity.Retrying(\n  File \"/home/runner/work/mysql-router-k8s-operator/mysql-router-k8s-operator/.tox/integration/lib/python3.10/site-packages/tenacity/__init__.py\", line 347, in __iter__\n    do = self.iter(retry_state=retry_state)\n  File \"/home/runner/work/mysql-router-k8s-operator/mysql-router-k8s-operator/.tox/integration/lib/python3.10/site-packages/tenacity/__init__.py\", line 325, in iter\n    raise retry_exc.reraise()\n  File \"/home/runner/work/mysql-router-k8s-operator/mysql-router-k8s-operator/.tox/integration/lib/python3.10/site-packages/tenacity/__init__.py\", line 158, in reraise\n    raise self.last_attempt.result()\n  File \"/usr/lib/python3.10/concurrent/futures/_base.py\", line 451, in result\n    return self.__get_result()\n  File \"/usr/lib/python3.10/concurrent/futures/_base.py\", line 403, in __get_result\n    raise self._exception\n  File \"/home/runner/work/mysql-router-k8s-operator/mysql-router-k8s-operator/tests/integration/test_exporter.py\", line 143, in test_exporter_endpoint\n    jmx_resp = http.request(\"GET\", f\"http://{unit_address}:49152/metrics\")\n  File \"/home/runner/work/mysql-router-k8s-operator/mysql-router-k8s-operator/.tox/integration/lib/python3.10/site-packages/urllib3/request.py\", line 74, in request\n    return self.request_encode_url(\n  File \"/home/runner/work/mysql-router-k8s-operator/mysql-router-k8s-operator/.tox/integration/lib/python3.10/site-packages/urllib3/request.py\", line 96, in request_encode_url\n    return self.urlopen(method, url, **extra_kw)\n  File \"/home/runner/work/mysql-router-k8s-operator/mysql-router-k8s-operator/.tox/integration/lib/python3.10/site-packages/urllib3/poolmanager.py\", line 376, in urlopen\n    response = conn.urlopen(method, u.request_uri, **kw)\n  File \"/home/runner/work/mysql-router-k8s-operator/mysql-router-k8s-operator/.tox/integration/lib/python3.10/site-packages/urllib3/connectionpool.py\", line 826, in urlopen\n    return self.urlopen(\n  File \"/home/runner/work/mysql-router-k8s-operator/mysql-router-k8s-operator/.tox/integration/lib/python3.10/site-packages/urllib3/connectionpool.py\", line 826, in urlopen\n    return self.urlopen(\n  File \"/home/runner/work/mysql-router-k8s-operator/mysql-router-k8s-operator/.tox/integration/lib/python3.10/site-packages/urllib3/connectionpool.py\", line 826, in urlopen\n    return self.urlopen(\n  File \"/home/runner/work/mysql-router-k8s-operator/mysql-router-k8s-operator/.tox/integration/lib/python3.10/site-packages/urllib3/connectionpool.py\", line 798, in urlopen\n    retries = retries.increment(\n  File \"/home/runner/work/mysql-router-k8s-operator/mysql-router-k8s-operator/.tox/integration/lib/python3.10/site-packages/urllib3/util/retry.py\", line 592, in increment\n    raise MaxRetryError(_pool, url, error or ResponseError(cause))\nurllib3.exceptions.MaxRetryError: HTTPConnectionPool(host='10.1.208.202', port=49152): Max retries exceeded with url: /metrics (Caused by NewConnectionError('<urllib3.connection.HTTPConnection object at 0x7f62886bd3f0>: Failed to establish a new connection: [Errno 111] Connection refused'))","flaky":false,"newFailed":false,"newBroken":true,"newPassed":false,"retriesCount":0,"retriesStatusChange":false,"beforeStages":[{"name":"tmp_path_factory","time":{"start":1714786525706,"stop":1714786525706,"duration":0},"status":"passed","steps":[],"attachments":[],"parameters":[],"stepsCount":0,"shouldDisplayMessage":false,"attachmentsCount":0,"hasContent":false,"attachmentStep":false},{"name":"ops_test","time":{"start":1714786525706,"stop":1714786525979,"duration":273},"status":"passed","steps":[],"attachments":[],"parameters":[],"stepsCount":0,"shouldDisplayMessage":false,"attachmentsCount":0,"hasContent":false,"attachmentStep":false},{"name":"event_loop","time":{"start":1714786525706,"stop":1714786525706,"duration":0},"status":"passed","steps":[],"attachments":[],"parameters":[],"stepsCount":0,"shouldDisplayMessage":false,"attachmentsCount":0,"hasContent":false,"attachmentStep":false},{"name":"abort_on_fail","time":{"start":1714786525979,"stop":1714786525979,"duration":0},"status":"passed","steps":[],"attachments":[],"parameters":[],"stepsCount":0,"shouldDisplayMessage":false,"attachmentsCount":0,"hasContent":false,"attachmentStep":false}],"testStage":{"description":"Test that exporter endpoint is functional.","status":"broken","statusMessage":"urllib3.exceptions.MaxRetryError: HTTPConnectionPool(host='10.1.208.202', port=49152): Max retries exceeded with url: /metrics (Caused by NewConnectionError('<urllib3.connection.HTTPConnection object at 0x7f62886bd3f0>: Failed to establish a new connection: [Errno 111] Connection refused'))","statusTrace":"Traceback (most recent call last):\n  File \"/home/runner/work/mysql-router-k8s-operator/mysql-router-k8s-operator/.tox/integration/lib/python3.10/site-packages/urllib3/connection.py\", line 174, in _new_conn\n    conn = connection.create_connection(\n  File \"/home/runner/work/mysql-router-k8s-operator/mysql-router-k8s-operator/.tox/integration/lib/python3.10/site-packages/urllib3/util/connection.py\", line 95, in create_connection\n    raise err\n  File \"/home/runner/work/mysql-router-k8s-operator/mysql-router-k8s-operator/.tox/integration/lib/python3.10/site-packages/urllib3/util/connection.py\", line 85, in create_connection\n    sock.connect(sa)\nConnectionRefusedError: [Errno 111] Connection refused\n\nDuring handling of the above exception, another exception occurred:\n\nTraceback (most recent call last):\n  File \"/home/runner/work/mysql-router-k8s-operator/mysql-router-k8s-operator/.tox/integration/lib/python3.10/site-packages/urllib3/connectionpool.py\", line 714, in urlopen\n    httplib_response = self._make_request(\n  File \"/home/runner/work/mysql-router-k8s-operator/mysql-router-k8s-operator/.tox/integration/lib/python3.10/site-packages/urllib3/connectionpool.py\", line 415, in _make_request\n    conn.request(method, url, **httplib_request_kw)\n  File \"/home/runner/work/mysql-router-k8s-operator/mysql-router-k8s-operator/.tox/integration/lib/python3.10/site-packages/urllib3/connection.py\", line 244, in request\n    super(HTTPConnection, self).request(method, url, body=body, headers=headers)\n  File \"/usr/lib/python3.10/http/client.py\", line 1283, in request\n    self._send_request(method, url, body, headers, encode_chunked)\n  File \"/usr/lib/python3.10/http/client.py\", line 1329, in _send_request\n    self.endheaders(body, encode_chunked=encode_chunked)\n  File \"/usr/lib/python3.10/http/client.py\", line 1278, in endheaders\n    self._send_output(message_body, encode_chunked=encode_chunked)\n  File \"/usr/lib/python3.10/http/client.py\", line 1038, in _send_output\n    self.send(msg)\n  File \"/usr/lib/python3.10/http/client.py\", line 976, in send\n    self.connect()\n  File \"/home/runner/work/mysql-router-k8s-operator/mysql-router-k8s-operator/.tox/integration/lib/python3.10/site-packages/urllib3/connection.py\", line 205, in connect\n    conn = self._new_conn()\n  File \"/home/runner/work/mysql-router-k8s-operator/mysql-router-k8s-operator/.tox/integration/lib/python3.10/site-packages/urllib3/connection.py\", line 186, in _new_conn\n    raise NewConnectionError(\nurllib3.exceptions.NewConnectionError: <urllib3.connection.HTTPConnection object at 0x7f62886bd3f0>: Failed to establish a new connection: [Errno 111] Connection refused\n\nDuring handling of the above exception, another exception occurred:\n\nTraceback (most recent call last):\n  File \"/home/runner/work/mysql-router-k8s-operator/mysql-router-k8s-operator/.tox/integration/lib/python3.10/site-packages/_pytest/runner.py\", line 341, in from_call\n    result: Optional[TResult] = func()\n  File \"/home/runner/work/mysql-router-k8s-operator/mysql-router-k8s-operator/.tox/integration/lib/python3.10/site-packages/_pytest/runner.py\", line 262, in <lambda>\n    lambda: ihook(item=item, **kwds), when=when, reraise=reraise\n  File \"/home/runner/work/mysql-router-k8s-operator/mysql-router-k8s-operator/.tox/integration/lib/python3.10/site-packages/pluggy/_hooks.py\", line 493, in __call__\n    return self._hookexec(self.name, self._hookimpls, kwargs, firstresult)\n  File \"/home/runner/work/mysql-router-k8s-operator/mysql-router-k8s-operator/.tox/integration/lib/python3.10/site-packages/pluggy/_manager.py\", line 115, in _hookexec\n    return self._inner_hookexec(hook_name, methods, kwargs, firstresult)\n  File \"/home/runner/work/mysql-router-k8s-operator/mysql-router-k8s-operator/.tox/integration/lib/python3.10/site-packages/pluggy/_callers.py\", line 152, in _multicall\n    return outcome.get_result()\n  File \"/home/runner/work/mysql-router-k8s-operator/mysql-router-k8s-operator/.tox/integration/lib/python3.10/site-packages/pluggy/_result.py\", line 114, in get_result\n    raise exc.with_traceback(exc.__traceback__)\n  File \"/home/runner/work/mysql-router-k8s-operator/mysql-router-k8s-operator/.tox/integration/lib/python3.10/site-packages/pluggy/_callers.py\", line 77, in _multicall\n    res = hook_impl.function(*args)\n  File \"/home/runner/work/mysql-router-k8s-operator/mysql-router-k8s-operator/.tox/integration/lib/python3.10/site-packages/_pytest/runner.py\", line 177, in pytest_runtest_call\n    raise e\n  File \"/home/runner/work/mysql-router-k8s-operator/mysql-router-k8s-operator/.tox/integration/lib/python3.10/site-packages/_pytest/runner.py\", line 169, in pytest_runtest_call\n    item.runtest()\n  File \"/home/runner/work/mysql-router-k8s-operator/mysql-router-k8s-operator/.tox/integration/lib/python3.10/site-packages/_pytest/python.py\", line 1788, in runtest\n    self.ihook.pytest_pyfunc_call(pyfuncitem=self)\n  File \"/home/runner/work/mysql-router-k8s-operator/mysql-router-k8s-operator/.tox/integration/lib/python3.10/site-packages/pluggy/_hooks.py\", line 493, in __call__\n    return self._hookexec(self.name, self._hookimpls, kwargs, firstresult)\n  File \"/home/runner/work/mysql-router-k8s-operator/mysql-router-k8s-operator/.tox/integration/lib/python3.10/site-packages/pluggy/_manager.py\", line 115, in _hookexec\n    return self._inner_hookexec(hook_name, methods, kwargs, firstresult)\n  File \"/home/runner/work/mysql-router-k8s-operator/mysql-router-k8s-operator/.tox/integration/lib/python3.10/site-packages/pluggy/_callers.py\", line 152, in _multicall\n    return outcome.get_result()\n  File \"/home/runner/work/mysql-router-k8s-operator/mysql-router-k8s-operator/.tox/integration/lib/python3.10/site-packages/pluggy/_result.py\", line 114, in get_result\n    raise exc.with_traceback(exc.__traceback__)\n  File \"/home/runner/work/mysql-router-k8s-operator/mysql-router-k8s-operator/.tox/integration/lib/python3.10/site-packages/pluggy/_callers.py\", line 77, in _multicall\n    res = hook_impl.function(*args)\n  File \"/home/runner/work/mysql-router-k8s-operator/mysql-router-k8s-operator/.tox/integration/lib/python3.10/site-packages/_pytest/python.py\", line 194, in pytest_pyfunc_call\n    result = testfunction(**testargs)\n  File \"/home/runner/work/mysql-router-k8s-operator/mysql-router-k8s-operator/.tox/integration/lib/python3.10/site-packages/pytest_asyncio/plugin.py\", line 532, in inner\n    _loop.run_until_complete(task)\n  File \"/usr/lib/python3.10/asyncio/base_events.py\", line 649, in run_until_complete\n    return future.result()\n  File \"/home/runner/work/mysql-router-k8s-operator/mysql-router-k8s-operator/tests/integration/test_exporter.py\", line 137, in test_exporter_endpoint\n    for attempt in tenacity.Retrying(\n  File \"/home/runner/work/mysql-router-k8s-operator/mysql-router-k8s-operator/.tox/integration/lib/python3.10/site-packages/tenacity/__init__.py\", line 347, in __iter__\n    do = self.iter(retry_state=retry_state)\n  File \"/home/runner/work/mysql-router-k8s-operator/mysql-router-k8s-operator/.tox/integration/lib/python3.10/site-packages/tenacity/__init__.py\", line 325, in iter\n    raise retry_exc.reraise()\n  File \"/home/runner/work/mysql-router-k8s-operator/mysql-router-k8s-operator/.tox/integration/lib/python3.10/site-packages/tenacity/__init__.py\", line 158, in reraise\n    raise self.last_attempt.result()\n  File \"/usr/lib/python3.10/concurrent/futures/_base.py\", line 451, in result\n    return self.__get_result()\n  File \"/usr/lib/python3.10/concurrent/futures/_base.py\", line 403, in __get_result\n    raise self._exception\n  File \"/home/runner/work/mysql-router-k8s-operator/mysql-router-k8s-operator/tests/integration/test_exporter.py\", line 143, in test_exporter_endpoint\n    jmx_resp = http.request(\"GET\", f\"http://{unit_address}:49152/metrics\")\n  File \"/home/runner/work/mysql-router-k8s-operator/mysql-router-k8s-operator/.tox/integration/lib/python3.10/site-packages/urllib3/request.py\", line 74, in request\n    return self.request_encode_url(\n  File \"/home/runner/work/mysql-router-k8s-operator/mysql-router-k8s-operator/.tox/integration/lib/python3.10/site-packages/urllib3/request.py\", line 96, in request_encode_url\n    return self.urlopen(method, url, **extra_kw)\n  File \"/home/runner/work/mysql-router-k8s-operator/mysql-router-k8s-operator/.tox/integration/lib/python3.10/site-packages/urllib3/poolmanager.py\", line 376, in urlopen\n    response = conn.urlopen(method, u.request_uri, **kw)\n  File \"/home/runner/work/mysql-router-k8s-operator/mysql-router-k8s-operator/.tox/integration/lib/python3.10/site-packages/urllib3/connectionpool.py\", line 826, in urlopen\n    return self.urlopen(\n  File \"/home/runner/work/mysql-router-k8s-operator/mysql-router-k8s-operator/.tox/integration/lib/python3.10/site-packages/urllib3/connectionpool.py\", line 826, in urlopen\n    return self.urlopen(\n  File \"/home/runner/work/mysql-router-k8s-operator/mysql-router-k8s-operator/.tox/integration/lib/python3.10/site-packages/urllib3/connectionpool.py\", line 826, in urlopen\n    return self.urlopen(\n  File \"/home/runner/work/mysql-router-k8s-operator/mysql-router-k8s-operator/.tox/integration/lib/python3.10/site-packages/urllib3/connectionpool.py\", line 798, in urlopen\n    retries = retries.increment(\n  File \"/home/runner/work/mysql-router-k8s-operator/mysql-router-k8s-operator/.tox/integration/lib/python3.10/site-packages/urllib3/util/retry.py\", line 592, in increment\n    raise MaxRetryError(_pool, url, error or ResponseError(cause))\nurllib3.exceptions.MaxRetryError: HTTPConnectionPool(host='10.1.208.202', port=49152): Max retries exceeded with url: /metrics (Caused by NewConnectionError('<urllib3.connection.HTTPConnection object at 0x7f62886bd3f0>: Failed to establish a new connection: [Errno 111] Connection refused'))","steps":[],"attachments":[{"uid":"c2043021acb7ff96","name":"log","source":"c2043021acb7ff96.txt","type":"text/plain","size":21968}],"parameters":[],"stepsCount":0,"shouldDisplayMessage":true,"attachmentsCount":1,"hasContent":true,"attachmentStep":false},"afterStages":[{"name":"abort_on_fail::0","time":{"start":1714786824197,"stop":1714786824197,"duration":0},"status":"passed","steps":[],"attachments":[],"parameters":[],"stepsCount":0,"shouldDisplayMessage":false,"attachmentsCount":0,"hasContent":false,"attachmentStep":false},{"name":"ops_test::finalizer","time":{"start":1714786824202,"stop":1714786844252,"duration":20050},"status":"passed","steps":[],"attachments":[],"parameters":[],"stepsCount":0,"shouldDisplayMessage":false,"attachmentsCount":0,"hasContent":false,"attachmentStep":false},{"name":"event_loop::2","time":{"start":1714786844253,"stop":1714786844253,"duration":0},"status":"passed","steps":[],"attachments":[],"parameters":[],"stepsCount":0,"shouldDisplayMessage":false,"attachmentsCount":0,"hasContent":false,"attachmentStep":false},{"name":"event_loop::_close_event_loop","time":{"start":1714786844253,"stop":1714786844253,"duration":0},"status":"passed","steps":[],"attachments":[],"parameters":[],"stepsCount":0,"shouldDisplayMessage":false,"attachmentsCount":0,"hasContent":false,"attachmentStep":false},{"name":"event_loop::_provide_clean_event_loop","time":{"start":1714786844253,"stop":1714786844253,"duration":0},"status":"passed","steps":[],"attachments":[],"parameters":[],"stepsCount":0,"shouldDisplayMessage":false,"attachmentsCount":0,"hasContent":false,"attachmentStep":false}],"labels":[{"name":"tag","value":"abort_on_fail"},{"name":"tag","value":"group(1)"},{"name":"tag","value":"asyncio"},{"name":"parentSuite","value":"tests.integration"},{"name":"suite","value":"test_exporter"},{"name":"host","value":"fv-az573-440"},{"name":"thread","value":"12359-MainThread"},{"name":"framework","value":"pytest"},{"name":"language","value":"cpython3"},{"name":"package","value":"tests.integration.test_exporter"},{"name":"resultFormat","value":"allure2"}],"parameters":[],"links":[],"hidden":false,"retry":false,"extra":{"severity":"normal","retries":[],"categories":[{"name":"Test defects","matchedStatuses":[],"flaky":false}],"history":{"statistic":{"failed":0,"broken":7,"skipped":0,"passed":18,"unknown":0,"total":25},"items":[{"uid":"19e2b20dec01c10","reportUrl":"../1353//#testresult/19e2b20dec01c10","status":"passed","time":{"start":1714700191416,"stop":1714700325763,"duration":134347}},{"uid":"75cd9cc9162901c7","reportUrl":"../1348//#testresult/75cd9cc9162901c7","status":"broken","statusDetails":"urllib3.exceptions.MaxRetryError: HTTPConnectionPool(host='10.1.79.139', port=49152): Max retries exceeded with url: /metrics (Caused by NewConnectionError('<urllib3.connection.HTTPConnection object at 0x7f92d8c08d00>: Failed to establish a new connection: [Errno 111] Connection refused'))","time":{"start":1714613465391,"stop":1714613758927,"duration":293536}},{"uid":"add77798314521b6","reportUrl":"../1342//#testresult/add77798314521b6","status":"passed","time":{"start":1714527119352,"stop":1714527254210,"duration":134858}},{"uid":"cb4fb4f0605a4b79","reportUrl":"../1338//#testresult/cb4fb4f0605a4b79","status":"passed","time":{"start":1714440740544,"stop":1714440882060,"duration":141516}},{"uid":"4db91bbbf3623512","reportUrl":"../1336//#testresult/4db91bbbf3623512","status":"passed","time":{"start":1714354302844,"stop":1714354451349,"duration":148505}},{"uid":"f2e113388432368d","reportUrl":"../1335//#testresult/f2e113388432368d","status":"passed","time":{"start":1714268092462,"stop":1714268235055,"duration":142593}},{"uid":"73e13693899ffcc3","reportUrl":"../1334//#testresult/73e13693899ffcc3","status":"passed","time":{"start":1714181420575,"stop":1714181561036,"duration":140461}},{"uid":"a67b030fbfea9e78","reportUrl":"../1330//#testresult/a67b030fbfea9e78","status":"passed","time":{"start":1714095069191,"stop":1714095218124,"duration":148933}},{"uid":"701e9f01a8791e0d","reportUrl":"../1328//#testresult/701e9f01a8791e0d","status":"passed","time":{"start":1714008693080,"stop":1714008830732,"duration":137652}},{"uid":"54422087759065db","reportUrl":"../1322//#testresult/54422087759065db","status":"passed","time":{"start":1713922428304,"stop":1713922596526,"duration":168222}},{"uid":"bcdd950323db84c5","reportUrl":"../1319//#testresult/bcdd950323db84c5","status":"passed","time":{"start":1713835887714,"stop":1713836070442,"duration":182728}},{"uid":"551797ed8a708771","reportUrl":"../1311//#testresult/551797ed8a708771","status":"passed","time":{"start":1713749490646,"stop":1713749671083,"duration":180437}},{"uid":"1e1a8362ebf1f97d","reportUrl":"../1310//#testresult/1e1a8362ebf1f97d","status":"passed","time":{"start":1713663117572,"stop":1713663295335,"duration":177763}},{"uid":"5cf2e41c62ca4c39","reportUrl":"../1309//#testresult/5cf2e41c62ca4c39","status":"passed","time":{"start":1713576584029,"stop":1713576767076,"duration":183047}},{"uid":"148541f25e2e12a8","reportUrl":"../1303//#testresult/148541f25e2e12a8","status":"passed","time":{"start":1713403784586,"stop":1713403963724,"duration":179138}},{"uid":"7e5b7b2e1b1e838f","reportUrl":"../1301//#testresult/7e5b7b2e1b1e838f","status":"passed","time":{"start":1713317474978,"stop":1713317657649,"duration":182671}},{"uid":"4e522f1b1ea74ff9","reportUrl":"../1300//#testresult/4e522f1b1ea74ff9","status":"passed","time":{"start":1713230998428,"stop":1713231197251,"duration":198823}},{"uid":"ca93b12b07387dc5","reportUrl":"../1299//#testresult/ca93b12b07387dc5","status":"passed","time":{"start":1713149626233,"stop":1713149805306,"duration":179073}},{"uid":"797ad6e16d96f824","reportUrl":"../1298//#testresult/797ad6e16d96f824","status":"broken","statusDetails":"urllib3.exceptions.MaxRetryError: HTTPConnectionPool(host='10.1.201.76', port=49152): Max retries exceeded with url: /metrics (Caused by NewConnectionError('<urllib3.connection.HTTPConnection object at 0x7f40fec63340>: Failed to establish a new connection: [Errno 111] Connection refused'))","time":{"start":1713058349800,"stop":1713058500700,"duration":150900}},{"uid":"c81820eb7bf8f9a","reportUrl":"../1297//#testresult/c81820eb7bf8f9a","status":"broken","statusDetails":"urllib3.exceptions.MaxRetryError: HTTPConnectionPool(host='10.1.183.136', port=49152): Max retries exceeded with url: /metrics (Caused by NewConnectionError('<urllib3.connection.HTTPConnection object at 0x7f681982d390>: Failed to establish a new connection: [Errno 111] Connection refused'))","time":{"start":1712971332969,"stop":1712971486958,"duration":153989}}]},"tags":["asyncio","abort_on_fail","group(1)"]},"source":"8eff7307c20b8ed7.json","parameterValues":[]}