[32mINFO    [0m pytest_operator.plugin:plugin.py:675 Connecting to existing model microk8s-localhost:test on unspecified cloud
[32mINFO    [0m integration.test_exporter:test_exporter.py:40 Deploying all the applications
[32mINFO    [0m juju.model:model.py:2069 Deploying ch:amd64/jammy/mysql-test-app-36
[32mINFO    [0m juju.model:model.py:2069 Deploying ch:amd64/jammy/mysql-k8s-136
[32mINFO    [0m juju.model:model.py:2069 Deploying ch:amd64/jammy/grafana-agent-k8s-64
[32mINFO    [0m juju.model:model.py:2069 Deploying local:jammy/mysql-router-k8s-0
[32mINFO    [0m integration.test_exporter:test_exporter.py:79 Waiting for mysqlrouter to be in BlockedStatus
[32mINFO    [0m integration.test_exporter:test_exporter.py:85 Relating mysql, mysqlrouter and application
[33mWARNING [0m juju.model:model.py:1558 relate is deprecated and will be removed. Use integrate instead.
[33mWARNING [0m juju.model:model.py:1558 relate is deprecated and will be removed. Use integrate instead.
[32mINFO    [0m juju.model:model.py:2759 Waiting for model:
  mysql-router-k8s/0 [executing] maintenance: Waiting for container
[32mINFO    [0m juju.model:model.py:2759 Waiting for model:
  mysql-router-k8s/0 [idle] waiting: 
[32mINFO    [0m juju.model:model.py:2759 Waiting for model:
  mysql-router-k8s/0 [idle] active: 
[32mINFO    [0m juju.model:model.py:2759 Waiting for model:
  mysql-k8s/0 [idle] active: Primary
  mysql-router-k8s/0 [idle] active: 
  mysql-test-app/0 [idle] active: 
[33mWARNING [0m urllib3.connectionpool:connectionpool.py:823 Retrying (Retry(total=2, connect=None, read=None, redirect=None, status=None)) after connection broken by 'NewConnectionError('<urllib3.connection.HTTPConnection object at 0x7f16c4283250>: Failed to establish a new connection: [Errno 111] Connection refused')': /metrics
[33mWARNING [0m urllib3.connectionpool:connectionpool.py:823 Retrying (Retry(total=1, connect=None, read=None, redirect=None, status=None)) after connection broken by 'NewConnectionError('<urllib3.connection.HTTPConnection object at 0x7f16c42837f0>: Failed to establish a new connection: [Errno 111] Connection refused')': /metrics
[33mWARNING [0m urllib3.connectionpool:connectionpool.py:823 Retrying (Retry(total=0, connect=None, read=None, redirect=None, status=None)) after connection broken by 'NewConnectionError('<urllib3.connection.HTTPConnection object at 0x7f16c4282f20>: Failed to establish a new connection: [Errno 111] Connection refused')': /metrics
[32mINFO    [0m integration.test_exporter:test_exporter.py:116 Relating mysqlrouter with grafana agent
[33mWARNING [0m juju.model:model.py:1558 relate is deprecated and will be removed. Use integrate instead.
[33mWARNING [0m juju.model:model.py:1558 relate is deprecated and will be removed. Use integrate instead.
[33mWARNING [0m juju.model:model.py:1558 relate is deprecated and will be removed. Use integrate instead.
[32mINFO    [0m integration.test_exporter:test_exporter.py:136 Removing relation between mysqlrouter and grafana agent
[33mWARNING [0m urllib3.connectionpool:connectionpool.py:823 Retrying (Retry(total=2, connect=None, read=None, redirect=None, status=None)) after connection broken by 'NewConnectionError('<urllib3.connection.HTTPConnection object at 0x7f16c4561300>: Failed to establish a new connection: [Errno 111] Connection refused')': /metrics
[33mWARNING [0m urllib3.connectionpool:connectionpool.py:823 Retrying (Retry(total=1, connect=None, read=None, redirect=None, status=None)) after connection broken by 'NewConnectionError('<urllib3.connection.HTTPConnection object at 0x7f16c3f70d30>: Failed to establish a new connection: [Errno 111] Connection refused')': /metrics
[33mWARNING [0m urllib3.connectionpool:connectionpool.py:823 Retrying (Retry(total=0, connect=None, read=None, redirect=None, status=None)) after connection broken by 'NewConnectionError('<urllib3.connection.HTTPConnection object at 0x7f16c3f71330>: Failed to establish a new connection: [Errno 111] Connection refused')': /metrics
[32mINFO    [0m pytest_operator.plugin:plugin.py:790 Model status:

Model  Controller          Cloud/Region        Version  SLA          Timestamp
test   microk8s-localhost  microk8s/localhost  3.1.6    unsupported  02:56:45Z

App                Version                  Status   Scale  Charm              Channel        Rev  Address         Exposed  Message
grafana-agent-k8s  0.35.2                   waiting      1  grafana-agent-k8s  latest/stable   64  10.152.183.86   no       installing agent
mysql-k8s          8.0.36-0ubuntu0.22.04.1  active       1  mysql-k8s          8.0/edge       136  10.152.183.19   no       
mysql-router-k8s   8.0.36-0ubuntu0.22.04.1  active       1  mysql-router-k8s                    0  10.152.183.67   no       
mysql-test-app     0.0.2                    active       1  mysql-test-app     latest/edge     36  10.152.183.236  no       

Unit                  Workload  Agent  Address     Ports  Message
grafana-agent-k8s/0*  blocked   idle   10.1.38.77         grafana-cloud-config: off, grafana-dashboards-provider: off
mysql-k8s/0*          active    idle   10.1.38.76         Primary
mysql-router-k8s/0*   active    idle   10.1.38.74         
mysql-test-app/0*     active    idle   10.1.38.72         

[32mINFO    [0m pytest_operator.plugin:plugin.py:796 Juju error logs:


[32mINFO    [0m pytest_operator.plugin:plugin.py:862 Forgetting main...
[1m[31mERROR   [0m websockets.client:protocol.py:1015 data transfer failed
Traceback (most recent call last):
  File "/home/runner/work/mysql-router-k8s-operator/mysql-router-k8s-operator/.tox/integration/lib/python3.10/site-packages/websockets/legacy/protocol.py", line 959, in transfer_data
    message = await self.read_message()
  File "/home/runner/work/mysql-router-k8s-operator/mysql-router-k8s-operator/.tox/integration/lib/python3.10/site-packages/websockets/legacy/protocol.py", line 1029, in read_message
    frame = await self.read_data_frame(max_size=self.max_size)
  File "/home/runner/work/mysql-router-k8s-operator/mysql-router-k8s-operator/.tox/integration/lib/python3.10/site-packages/websockets/legacy/protocol.py", line 1104, in read_data_frame
    frame = await self.read_frame(max_size)
  File "/home/runner/work/mysql-router-k8s-operator/mysql-router-k8s-operator/.tox/integration/lib/python3.10/site-packages/websockets/legacy/protocol.py", line 1161, in read_frame
    frame = await Frame.read(
  File "/home/runner/work/mysql-router-k8s-operator/mysql-router-k8s-operator/.tox/integration/lib/python3.10/site-packages/websockets/legacy/framing.py", line 68, in read
    data = await reader(2)
  File "/usr/lib/python3.10/asyncio/streams.py", line 708, in readexactly
    await self._wait_for_data('readexactly')
  File "/usr/lib/python3.10/asyncio/streams.py", line 501, in _wait_for_data
    await self._waiter
  File "/usr/lib/python3.10/asyncio/selector_events.py", line 924, in write
    n = self._sock.send(data)
OSError: [Errno 9] Bad file descriptor